{
  "cells": [
    {
      "cell_type": "markdown",
      "metadata": {
        "colab_type": "text",
        "id": "view-in-github"
      },
      "source": [
        "<a href=\"https://colab.research.google.com/github/federico-riccardi/TesinaMOR/blob/main/Progetto.ipynb\" target=\"_parent\"><img src=\"https://colab.research.google.com/assets/colab-badge.svg\" alt=\"Open In Colab\"/></a>"
      ]
    },
    {
      "attachments": {},
      "cell_type": "markdown",
      "metadata": {},
      "source": [
        "CLONING THE REPOSITORY"
      ]
    },
    {
      "cell_type": "code",
      "execution_count": 33,
      "metadata": {},
      "outputs": [
        {
          "name": "stdout",
          "output_type": "stream",
          "text": [
            "Cloning into 'CppToPython'...\n",
            "remote: Enumerating objects: 645, done.\u001b[K\n",
            "remote: Counting objects: 100% (158/158), done.\u001b[K\n",
            "remote: Compressing objects: 100% (139/139), done.\u001b[K\n",
            "remote: Total 645 (delta 31), reused 50 (delta 17), pack-reused 487\u001b[K\n",
            "Receiving objects: 100% (645/645), 596.41 KiB | 1.69 MiB/s, done.\n",
            "Resolving deltas: 100% (424/424), done.\n",
            "/Users/lucamana/.Trash/CppToPython/CppToPython/CppToPython/CppToPython/CppToPython\n"
          ]
        }
      ],
      "source": [
        "!git clone https://github.com/fvicini/CppToPython.git\n",
        "%cd CppToPython"
      ]
    },
    {
      "cell_type": "code",
      "execution_count": 29,
      "metadata": {},
      "outputs": [],
      "source": [
        "!git submodule init\n",
        "!git submodule update"
      ]
    },
    {
      "attachments": {},
      "cell_type": "markdown",
      "metadata": {},
      "source": [
        "COMPILING THE EXTERNALS"
      ]
    },
    {
      "cell_type": "code",
      "execution_count": 32,
      "metadata": {
        "vscode": {
          "languageId": "shellscript"
        }
      },
      "outputs": [
        {
          "ename": "FileNotFoundError",
          "evalue": "[Errno 2] No such file or directory: 'mkdir -p externals'",
          "output_type": "error",
          "traceback": [
            "\u001b[0;31m---------------------------------------------------------------------------\u001b[0m",
            "\u001b[0;31mFileNotFoundError\u001b[0m                         Traceback (most recent call last)",
            "\u001b[0;32m/var/folders/2l/rvv41wt170b6m1d28j26znfc0000gn/T/ipykernel_8974/2347456575.py\u001b[0m in \u001b[0;36m<module>\u001b[0;34m\u001b[0m\n\u001b[1;32m      1\u001b[0m \u001b[0;32mimport\u001b[0m \u001b[0msubprocess\u001b[0m\u001b[0;34m\u001b[0m\u001b[0;34m\u001b[0m\u001b[0m\n\u001b[0;32m----> 2\u001b[0;31m \u001b[0msubprocess\u001b[0m\u001b[0;34m.\u001b[0m\u001b[0mrun\u001b[0m\u001b[0;34m(\u001b[0m\u001b[0;34m[\u001b[0m\u001b[0;34m\"mkdir -p externals\"\u001b[0m\u001b[0;34m]\u001b[0m\u001b[0;34m)\u001b[0m\u001b[0;34m\u001b[0m\u001b[0;34m\u001b[0m\u001b[0m\n\u001b[0m\u001b[1;32m      3\u001b[0m \u001b[0mget_ipython\u001b[0m\u001b[0;34m(\u001b[0m\u001b[0;34m)\u001b[0m\u001b[0;34m.\u001b[0m\u001b[0mrun_line_magic\u001b[0m\u001b[0;34m(\u001b[0m\u001b[0;34m'cd'\u001b[0m\u001b[0;34m,\u001b[0m \u001b[0;34m'externals'\u001b[0m\u001b[0;34m)\u001b[0m\u001b[0;34m\u001b[0m\u001b[0;34m\u001b[0m\u001b[0m\n\u001b[1;32m      4\u001b[0m \u001b[0mget_ipython\u001b[0m\u001b[0;34m(\u001b[0m\u001b[0;34m)\u001b[0m\u001b[0;34m.\u001b[0m\u001b[0msystem\u001b[0m\u001b[0;34m(\u001b[0m\u001b[0;34m'cmake -DINSTALL_VTK=OFF -DINSTALL_LAPACK=OFF ../gedim/3rd_party_libraries'\u001b[0m\u001b[0;34m)\u001b[0m\u001b[0;34m\u001b[0m\u001b[0;34m\u001b[0m\u001b[0m\n\u001b[1;32m      5\u001b[0m \u001b[0mget_ipython\u001b[0m\u001b[0;34m(\u001b[0m\u001b[0;34m)\u001b[0m\u001b[0;34m.\u001b[0m\u001b[0msystem\u001b[0m\u001b[0;34m(\u001b[0m\u001b[0;34m'make -j4'\u001b[0m\u001b[0;34m)\u001b[0m\u001b[0;34m\u001b[0m\u001b[0;34m\u001b[0m\u001b[0m\n",
            "\u001b[0;32m~/opt/anaconda3/lib/python3.9/subprocess.py\u001b[0m in \u001b[0;36mrun\u001b[0;34m(input, capture_output, timeout, check, *popenargs, **kwargs)\u001b[0m\n\u001b[1;32m    503\u001b[0m         \u001b[0mkwargs\u001b[0m\u001b[0;34m[\u001b[0m\u001b[0;34m'stderr'\u001b[0m\u001b[0;34m]\u001b[0m \u001b[0;34m=\u001b[0m \u001b[0mPIPE\u001b[0m\u001b[0;34m\u001b[0m\u001b[0;34m\u001b[0m\u001b[0m\n\u001b[1;32m    504\u001b[0m \u001b[0;34m\u001b[0m\u001b[0m\n\u001b[0;32m--> 505\u001b[0;31m     \u001b[0;32mwith\u001b[0m \u001b[0mPopen\u001b[0m\u001b[0;34m(\u001b[0m\u001b[0;34m*\u001b[0m\u001b[0mpopenargs\u001b[0m\u001b[0;34m,\u001b[0m \u001b[0;34m**\u001b[0m\u001b[0mkwargs\u001b[0m\u001b[0;34m)\u001b[0m \u001b[0;32mas\u001b[0m \u001b[0mprocess\u001b[0m\u001b[0;34m:\u001b[0m\u001b[0;34m\u001b[0m\u001b[0;34m\u001b[0m\u001b[0m\n\u001b[0m\u001b[1;32m    506\u001b[0m         \u001b[0;32mtry\u001b[0m\u001b[0;34m:\u001b[0m\u001b[0;34m\u001b[0m\u001b[0;34m\u001b[0m\u001b[0m\n\u001b[1;32m    507\u001b[0m             \u001b[0mstdout\u001b[0m\u001b[0;34m,\u001b[0m \u001b[0mstderr\u001b[0m \u001b[0;34m=\u001b[0m \u001b[0mprocess\u001b[0m\u001b[0;34m.\u001b[0m\u001b[0mcommunicate\u001b[0m\u001b[0;34m(\u001b[0m\u001b[0minput\u001b[0m\u001b[0;34m,\u001b[0m \u001b[0mtimeout\u001b[0m\u001b[0;34m=\u001b[0m\u001b[0mtimeout\u001b[0m\u001b[0;34m)\u001b[0m\u001b[0;34m\u001b[0m\u001b[0;34m\u001b[0m\u001b[0m\n",
            "\u001b[0;32m~/opt/anaconda3/lib/python3.9/subprocess.py\u001b[0m in \u001b[0;36m__init__\u001b[0;34m(self, args, bufsize, executable, stdin, stdout, stderr, preexec_fn, close_fds, shell, cwd, env, universal_newlines, startupinfo, creationflags, restore_signals, start_new_session, pass_fds, user, group, extra_groups, encoding, errors, text, umask)\u001b[0m\n\u001b[1;32m    949\u001b[0m                             encoding=encoding, errors=errors)\n\u001b[1;32m    950\u001b[0m \u001b[0;34m\u001b[0m\u001b[0m\n\u001b[0;32m--> 951\u001b[0;31m             self._execute_child(args, executable, preexec_fn, close_fds,\n\u001b[0m\u001b[1;32m    952\u001b[0m                                 \u001b[0mpass_fds\u001b[0m\u001b[0;34m,\u001b[0m \u001b[0mcwd\u001b[0m\u001b[0;34m,\u001b[0m \u001b[0menv\u001b[0m\u001b[0;34m,\u001b[0m\u001b[0;34m\u001b[0m\u001b[0;34m\u001b[0m\u001b[0m\n\u001b[1;32m    953\u001b[0m                                 \u001b[0mstartupinfo\u001b[0m\u001b[0;34m,\u001b[0m \u001b[0mcreationflags\u001b[0m\u001b[0;34m,\u001b[0m \u001b[0mshell\u001b[0m\u001b[0;34m,\u001b[0m\u001b[0;34m\u001b[0m\u001b[0;34m\u001b[0m\u001b[0m\n",
            "\u001b[0;32m~/opt/anaconda3/lib/python3.9/subprocess.py\u001b[0m in \u001b[0;36m_execute_child\u001b[0;34m(self, args, executable, preexec_fn, close_fds, pass_fds, cwd, env, startupinfo, creationflags, shell, p2cread, p2cwrite, c2pread, c2pwrite, errread, errwrite, restore_signals, gid, gids, uid, umask, start_new_session)\u001b[0m\n\u001b[1;32m   1819\u001b[0m                     \u001b[0;32mif\u001b[0m \u001b[0merrno_num\u001b[0m \u001b[0;34m!=\u001b[0m \u001b[0;36m0\u001b[0m\u001b[0;34m:\u001b[0m\u001b[0;34m\u001b[0m\u001b[0;34m\u001b[0m\u001b[0m\n\u001b[1;32m   1820\u001b[0m                         \u001b[0merr_msg\u001b[0m \u001b[0;34m=\u001b[0m \u001b[0mos\u001b[0m\u001b[0;34m.\u001b[0m\u001b[0mstrerror\u001b[0m\u001b[0;34m(\u001b[0m\u001b[0merrno_num\u001b[0m\u001b[0;34m)\u001b[0m\u001b[0;34m\u001b[0m\u001b[0;34m\u001b[0m\u001b[0m\n\u001b[0;32m-> 1821\u001b[0;31m                     \u001b[0;32mraise\u001b[0m \u001b[0mchild_exception_type\u001b[0m\u001b[0;34m(\u001b[0m\u001b[0merrno_num\u001b[0m\u001b[0;34m,\u001b[0m \u001b[0merr_msg\u001b[0m\u001b[0;34m,\u001b[0m \u001b[0merr_filename\u001b[0m\u001b[0;34m)\u001b[0m\u001b[0;34m\u001b[0m\u001b[0;34m\u001b[0m\u001b[0m\n\u001b[0m\u001b[1;32m   1822\u001b[0m                 \u001b[0;32mraise\u001b[0m \u001b[0mchild_exception_type\u001b[0m\u001b[0;34m(\u001b[0m\u001b[0merr_msg\u001b[0m\u001b[0;34m)\u001b[0m\u001b[0;34m\u001b[0m\u001b[0;34m\u001b[0m\u001b[0m\n\u001b[1;32m   1823\u001b[0m \u001b[0;34m\u001b[0m\u001b[0m\n",
            "\u001b[0;31mFileNotFoundError\u001b[0m: [Errno 2] No such file or directory: 'mkdir -p externals'"
          ]
        }
      ],
      "source": [
        "import subprocess\n",
        "subprocess.run([\"mkdir -p externals\"])\n",
        "%cd externals\n",
        "!cmake -DINSTALL_VTK=OFF -DINSTALL_LAPACK=OFF ../gedim/3rd_party_libraries\n",
        "!make -j4\n",
        "%cd .."
      ]
    },
    {
      "attachments": {},
      "cell_type": "markdown",
      "metadata": {},
      "source": [
        "COMPILING THE C++ LIBRARY"
      ]
    },
    {
      "cell_type": "code",
      "execution_count": 27,
      "metadata": {},
      "outputs": [
        {
          "ename": "FileNotFoundError",
          "evalue": "[Errno 2] No such file or directory: 'mkdir -p release'",
          "output_type": "error",
          "traceback": [
            "\u001b[0;31m---------------------------------------------------------------------------\u001b[0m",
            "\u001b[0;31mFileNotFoundError\u001b[0m                         Traceback (most recent call last)",
            "\u001b[0;32m/var/folders/2l/rvv41wt170b6m1d28j26znfc0000gn/T/ipykernel_8974/142936959.py\u001b[0m in \u001b[0;36m<module>\u001b[0;34m\u001b[0m\n\u001b[1;32m      1\u001b[0m \u001b[0;32mimport\u001b[0m \u001b[0msubprocess\u001b[0m\u001b[0;34m\u001b[0m\u001b[0;34m\u001b[0m\u001b[0m\n\u001b[1;32m      2\u001b[0m \u001b[0mpath\u001b[0m  \u001b[0;34m=\u001b[0m \u001b[0;34m\"/content/CppToPython/externals/Main_Install/eigen3;/content/CppToPython/externals/Main_Install/triangle;/content/CppToPython/externals/Main_Install/tetgen;/content/CppToPython/externals/Main_Install/googletest\"\u001b[0m\u001b[0;34m\u001b[0m\u001b[0;34m\u001b[0m\u001b[0m\n\u001b[0;32m----> 3\u001b[0;31m subprocess.run([\n\u001b[0m\u001b[1;32m      4\u001b[0m     \u001b[0;34m\"mkdir -p release\"\u001b[0m\u001b[0;34m,\u001b[0m\u001b[0;34m\u001b[0m\u001b[0;34m\u001b[0m\u001b[0m\n\u001b[1;32m      5\u001b[0m     \u001b[0;34m\"cd release \"\u001b[0m\u001b[0;34m,\u001b[0m\u001b[0;34m\u001b[0m\u001b[0;34m\u001b[0m\u001b[0m\n",
            "\u001b[0;32m~/opt/anaconda3/lib/python3.9/subprocess.py\u001b[0m in \u001b[0;36mrun\u001b[0;34m(input, capture_output, timeout, check, *popenargs, **kwargs)\u001b[0m\n\u001b[1;32m    503\u001b[0m         \u001b[0mkwargs\u001b[0m\u001b[0;34m[\u001b[0m\u001b[0;34m'stderr'\u001b[0m\u001b[0;34m]\u001b[0m \u001b[0;34m=\u001b[0m \u001b[0mPIPE\u001b[0m\u001b[0;34m\u001b[0m\u001b[0;34m\u001b[0m\u001b[0m\n\u001b[1;32m    504\u001b[0m \u001b[0;34m\u001b[0m\u001b[0m\n\u001b[0;32m--> 505\u001b[0;31m     \u001b[0;32mwith\u001b[0m \u001b[0mPopen\u001b[0m\u001b[0;34m(\u001b[0m\u001b[0;34m*\u001b[0m\u001b[0mpopenargs\u001b[0m\u001b[0;34m,\u001b[0m \u001b[0;34m**\u001b[0m\u001b[0mkwargs\u001b[0m\u001b[0;34m)\u001b[0m \u001b[0;32mas\u001b[0m \u001b[0mprocess\u001b[0m\u001b[0;34m:\u001b[0m\u001b[0;34m\u001b[0m\u001b[0;34m\u001b[0m\u001b[0m\n\u001b[0m\u001b[1;32m    506\u001b[0m         \u001b[0;32mtry\u001b[0m\u001b[0;34m:\u001b[0m\u001b[0;34m\u001b[0m\u001b[0;34m\u001b[0m\u001b[0m\n\u001b[1;32m    507\u001b[0m             \u001b[0mstdout\u001b[0m\u001b[0;34m,\u001b[0m \u001b[0mstderr\u001b[0m \u001b[0;34m=\u001b[0m \u001b[0mprocess\u001b[0m\u001b[0;34m.\u001b[0m\u001b[0mcommunicate\u001b[0m\u001b[0;34m(\u001b[0m\u001b[0minput\u001b[0m\u001b[0;34m,\u001b[0m \u001b[0mtimeout\u001b[0m\u001b[0;34m=\u001b[0m\u001b[0mtimeout\u001b[0m\u001b[0;34m)\u001b[0m\u001b[0;34m\u001b[0m\u001b[0;34m\u001b[0m\u001b[0m\n",
            "\u001b[0;32m~/opt/anaconda3/lib/python3.9/subprocess.py\u001b[0m in \u001b[0;36m__init__\u001b[0;34m(self, args, bufsize, executable, stdin, stdout, stderr, preexec_fn, close_fds, shell, cwd, env, universal_newlines, startupinfo, creationflags, restore_signals, start_new_session, pass_fds, user, group, extra_groups, encoding, errors, text, umask)\u001b[0m\n\u001b[1;32m    949\u001b[0m                             encoding=encoding, errors=errors)\n\u001b[1;32m    950\u001b[0m \u001b[0;34m\u001b[0m\u001b[0m\n\u001b[0;32m--> 951\u001b[0;31m             self._execute_child(args, executable, preexec_fn, close_fds,\n\u001b[0m\u001b[1;32m    952\u001b[0m                                 \u001b[0mpass_fds\u001b[0m\u001b[0;34m,\u001b[0m \u001b[0mcwd\u001b[0m\u001b[0;34m,\u001b[0m \u001b[0menv\u001b[0m\u001b[0;34m,\u001b[0m\u001b[0;34m\u001b[0m\u001b[0;34m\u001b[0m\u001b[0m\n\u001b[1;32m    953\u001b[0m                                 \u001b[0mstartupinfo\u001b[0m\u001b[0;34m,\u001b[0m \u001b[0mcreationflags\u001b[0m\u001b[0;34m,\u001b[0m \u001b[0mshell\u001b[0m\u001b[0;34m,\u001b[0m\u001b[0;34m\u001b[0m\u001b[0;34m\u001b[0m\u001b[0m\n",
            "\u001b[0;32m~/opt/anaconda3/lib/python3.9/subprocess.py\u001b[0m in \u001b[0;36m_execute_child\u001b[0;34m(self, args, executable, preexec_fn, close_fds, pass_fds, cwd, env, startupinfo, creationflags, shell, p2cread, p2cwrite, c2pread, c2pwrite, errread, errwrite, restore_signals, gid, gids, uid, umask, start_new_session)\u001b[0m\n\u001b[1;32m   1819\u001b[0m                     \u001b[0;32mif\u001b[0m \u001b[0merrno_num\u001b[0m \u001b[0;34m!=\u001b[0m \u001b[0;36m0\u001b[0m\u001b[0;34m:\u001b[0m\u001b[0;34m\u001b[0m\u001b[0;34m\u001b[0m\u001b[0m\n\u001b[1;32m   1820\u001b[0m                         \u001b[0merr_msg\u001b[0m \u001b[0;34m=\u001b[0m \u001b[0mos\u001b[0m\u001b[0;34m.\u001b[0m\u001b[0mstrerror\u001b[0m\u001b[0;34m(\u001b[0m\u001b[0merrno_num\u001b[0m\u001b[0;34m)\u001b[0m\u001b[0;34m\u001b[0m\u001b[0;34m\u001b[0m\u001b[0m\n\u001b[0;32m-> 1821\u001b[0;31m                     \u001b[0;32mraise\u001b[0m \u001b[0mchild_exception_type\u001b[0m\u001b[0;34m(\u001b[0m\u001b[0merrno_num\u001b[0m\u001b[0;34m,\u001b[0m \u001b[0merr_msg\u001b[0m\u001b[0;34m,\u001b[0m \u001b[0merr_filename\u001b[0m\u001b[0;34m)\u001b[0m\u001b[0;34m\u001b[0m\u001b[0;34m\u001b[0m\u001b[0m\n\u001b[0m\u001b[1;32m   1822\u001b[0m                 \u001b[0;32mraise\u001b[0m \u001b[0mchild_exception_type\u001b[0m\u001b[0;34m(\u001b[0m\u001b[0merr_msg\u001b[0m\u001b[0;34m)\u001b[0m\u001b[0;34m\u001b[0m\u001b[0;34m\u001b[0m\u001b[0m\n\u001b[1;32m   1823\u001b[0m \u001b[0;34m\u001b[0m\u001b[0m\n",
            "\u001b[0;31mFileNotFoundError\u001b[0m: [Errno 2] No such file or directory: 'mkdir -p release'"
          ]
        }
      ],
      "source": [
        "\n",
        "path  = \"/content/CppToPython/externals/Main_Install/eigen3;/content/CppToPython/externals/Main_Install/triangle;/content/CppToPython/externals/Main_Install/tetgen;/content/CppToPython/externals/Main_Install/googletest\"\n",
        "subprocess.run([\n",
        "    \"mkdir -p release\",\n",
        "    \"cd release \",\n",
        "    \"cmake -DCMAKE_PREFIX_PATH= ../ \",\n",
        "    \"make -j4 GeDiM4Py\",\n",
        "    \"cd ..\"\n",
        "])"
      ]
    },
    {
      "attachments": {},
      "cell_type": "markdown",
      "metadata": {},
      "source": [
        "IMPORTING LIBRARY"
      ]
    },
    {
      "cell_type": "code",
      "execution_count": 13,
      "metadata": {},
      "outputs": [],
      "source": [
        "import numpy as np\n",
        "import GeDiM4Py as gedim"
      ]
    },
    {
      "attachments": {},
      "cell_type": "markdown",
      "metadata": {},
      "source": [
        "INITIALIZE"
      ]
    },
    {
      "cell_type": "code",
      "execution_count": 14,
      "metadata": {},
      "outputs": [
        {
          "ename": "OSError",
          "evalue": "dlopen(./release/GeDiM4Py.so, 0x0006): tried: './release/GeDiM4Py.so' (no such file), '/System/Volumes/Preboot/Cryptexes/OS./release/GeDiM4Py.so' (no such file), '/Users/lucamana/opt/anaconda3/lib/python3.9/lib-dynload/../.././release/GeDiM4Py.so' (no such file), '/Users/lucamana/opt/anaconda3/bin/../lib/./release/GeDiM4Py.so' (no such file), '/usr/lib/./release/GeDiM4Py.so' (no such file, not in dyld cache), './release/GeDiM4Py.so' (no such file), '/Users/lucamana/Desktop/Polito/TesinaMOR/CppToPython/CppToPython/CppToPython/release/GeDiM4Py.so' (no such file), '/System/Volumes/Preboot/Cryptexes/OS/Users/lucamana/Desktop/Polito/TesinaMOR/CppToPython/CppToPython/CppToPython/release/GeDiM4Py.so' (no such file), '/Users/lucamana/Desktop/Polito/TesinaMOR/CppToPython/CppToPython/CppToPython/release/GeDiM4Py.so' (no such file)",
          "output_type": "error",
          "traceback": [
            "\u001b[0;31m---------------------------------------------------------------------------\u001b[0m",
            "\u001b[0;31mOSError\u001b[0m                                   Traceback (most recent call last)",
            "\u001b[0;32m/var/folders/2l/rvv41wt170b6m1d28j26znfc0000gn/T/ipykernel_8974/1907965304.py\u001b[0m in \u001b[0;36m<module>\u001b[0;34m\u001b[0m\n\u001b[0;32m----> 1\u001b[0;31m \u001b[0mlib\u001b[0m \u001b[0;34m=\u001b[0m \u001b[0mgedim\u001b[0m\u001b[0;34m.\u001b[0m\u001b[0mImportLibrary\u001b[0m\u001b[0;34m(\u001b[0m\u001b[0;34m\"./release/GeDiM4Py.so\"\u001b[0m\u001b[0;34m)\u001b[0m\u001b[0;34m\u001b[0m\u001b[0;34m\u001b[0m\u001b[0m\n\u001b[0m\u001b[1;32m      2\u001b[0m \u001b[0;34m\u001b[0m\u001b[0m\n\u001b[1;32m      3\u001b[0m \u001b[0mconfig\u001b[0m \u001b[0;34m=\u001b[0m \u001b[0;34m{\u001b[0m \u001b[0;34m'GeometricTolerance'\u001b[0m\u001b[0;34m:\u001b[0m \u001b[0;36m1.0e-8\u001b[0m \u001b[0;34m}\u001b[0m\u001b[0;34m\u001b[0m\u001b[0;34m\u001b[0m\u001b[0m\n\u001b[1;32m      4\u001b[0m \u001b[0mgedim\u001b[0m\u001b[0;34m.\u001b[0m\u001b[0mInitialize\u001b[0m\u001b[0;34m(\u001b[0m\u001b[0mconfig\u001b[0m\u001b[0;34m,\u001b[0m \u001b[0mlib\u001b[0m\u001b[0;34m)\u001b[0m\u001b[0;34m\u001b[0m\u001b[0;34m\u001b[0m\u001b[0m\n",
            "\u001b[0;32m~/Desktop/Polito/TesinaMOR/CppToPython/GeDiM4Py.py\u001b[0m in \u001b[0;36mImportLibrary\u001b[0;34m(path)\u001b[0m\n\u001b[1;32m     51\u001b[0m \u001b[0;34m\u001b[0m\u001b[0m\n\u001b[1;32m     52\u001b[0m \u001b[0;32mdef\u001b[0m \u001b[0mImportLibrary\u001b[0m\u001b[0;34m(\u001b[0m\u001b[0mpath\u001b[0m\u001b[0;34m)\u001b[0m\u001b[0;34m:\u001b[0m\u001b[0;34m\u001b[0m\u001b[0;34m\u001b[0m\u001b[0m\n\u001b[0;32m---> 53\u001b[0;31m         \u001b[0;32mreturn\u001b[0m \u001b[0mct\u001b[0m\u001b[0;34m.\u001b[0m\u001b[0mPyDLL\u001b[0m\u001b[0;34m(\u001b[0m\u001b[0mpath\u001b[0m\u001b[0;34m)\u001b[0m\u001b[0;34m\u001b[0m\u001b[0;34m\u001b[0m\u001b[0m\n\u001b[0m\u001b[1;32m     54\u001b[0m         \u001b[0;31m#return ct.cdll.LoadLibrary(path)\u001b[0m\u001b[0;34m\u001b[0m\u001b[0;34m\u001b[0m\u001b[0m\n\u001b[1;32m     55\u001b[0m \u001b[0;34m\u001b[0m\u001b[0m\n",
            "\u001b[0;32m~/opt/anaconda3/lib/python3.9/ctypes/__init__.py\u001b[0m in \u001b[0;36m__init__\u001b[0;34m(self, name, mode, handle, use_errno, use_last_error, winmode)\u001b[0m\n\u001b[1;32m    380\u001b[0m \u001b[0;34m\u001b[0m\u001b[0m\n\u001b[1;32m    381\u001b[0m         \u001b[0;32mif\u001b[0m \u001b[0mhandle\u001b[0m \u001b[0;32mis\u001b[0m \u001b[0;32mNone\u001b[0m\u001b[0;34m:\u001b[0m\u001b[0;34m\u001b[0m\u001b[0;34m\u001b[0m\u001b[0m\n\u001b[0;32m--> 382\u001b[0;31m             \u001b[0mself\u001b[0m\u001b[0;34m.\u001b[0m\u001b[0m_handle\u001b[0m \u001b[0;34m=\u001b[0m \u001b[0m_dlopen\u001b[0m\u001b[0;34m(\u001b[0m\u001b[0mself\u001b[0m\u001b[0;34m.\u001b[0m\u001b[0m_name\u001b[0m\u001b[0;34m,\u001b[0m \u001b[0mmode\u001b[0m\u001b[0;34m)\u001b[0m\u001b[0;34m\u001b[0m\u001b[0;34m\u001b[0m\u001b[0m\n\u001b[0m\u001b[1;32m    383\u001b[0m         \u001b[0;32melse\u001b[0m\u001b[0;34m:\u001b[0m\u001b[0;34m\u001b[0m\u001b[0;34m\u001b[0m\u001b[0m\n\u001b[1;32m    384\u001b[0m             \u001b[0mself\u001b[0m\u001b[0;34m.\u001b[0m\u001b[0m_handle\u001b[0m \u001b[0;34m=\u001b[0m \u001b[0mhandle\u001b[0m\u001b[0;34m\u001b[0m\u001b[0;34m\u001b[0m\u001b[0m\n",
            "\u001b[0;31mOSError\u001b[0m: dlopen(./release/GeDiM4Py.so, 0x0006): tried: './release/GeDiM4Py.so' (no such file), '/System/Volumes/Preboot/Cryptexes/OS./release/GeDiM4Py.so' (no such file), '/Users/lucamana/opt/anaconda3/lib/python3.9/lib-dynload/../.././release/GeDiM4Py.so' (no such file), '/Users/lucamana/opt/anaconda3/bin/../lib/./release/GeDiM4Py.so' (no such file), '/usr/lib/./release/GeDiM4Py.so' (no such file, not in dyld cache), './release/GeDiM4Py.so' (no such file), '/Users/lucamana/Desktop/Polito/TesinaMOR/CppToPython/CppToPython/CppToPython/release/GeDiM4Py.so' (no such file), '/System/Volumes/Preboot/Cryptexes/OS/Users/lucamana/Desktop/Polito/TesinaMOR/CppToPython/CppToPython/CppToPython/release/GeDiM4Py.so' (no such file), '/Users/lucamana/Desktop/Polito/TesinaMOR/CppToPython/CppToPython/CppToPython/release/GeDiM4Py.so' (no such file)"
          ]
        }
      ],
      "source": [
        "lib = gedim.ImportLibrary(\"./release/GeDiM4Py.so\")\n",
        "\n",
        "config = { 'GeometricTolerance': 1.0e-8 }\n",
        "gedim.Initialize(config, lib)"
      ]
    }
  ],
  "metadata": {
    "colab": {
      "authorship_tag": "ABX9TyP0oU7afdsn624RWDlIVs6s",
      "include_colab_link": true,
      "provenance": []
    },
    "kernelspec": {
      "display_name": "Python 3",
      "name": "python3"
    },
    "language_info": {
      "name": "python"
    }
  },
  "nbformat": 4,
  "nbformat_minor": 0
}
